Workbook
Name Slicer_Parameter: #N/A
Name Slicer_Parameters: #N/A
Name Slicer_Stages: #N/A
Name Slicer_Stages1: #N/A

Sheet Report Book
A1: Date | C1: ZLD Plant Inlet (MEE CONDENSATE) | AB1: R-503 | AI1: Tube Settler Overflow (TS-501) | AO1: ASP - 501 INLET | AX1: ASP - 501 (Tank) | BJ1: SC-501 O/F | BS1: SC-501 U/F | BU1: Inside MBBR Tank-1 | CC1: Inside MBBR Tank-2 | CL1: Tube Settler Overflow (TS-502) | CT1: Gravity Sand Filter Outlet | DA1: T-511 Storage Tank (Without Filtration) | DI1: T-513 Storage Tank | DN1: SCP 501 MAP FILTRATE | DT1: SCP-501 MAP SLUDGE | DX1: MBR Feed | EG1: MBR Permeate | EP1: SPIRAL RO FEED | EW1: SPIRAL RO PERMEATE | FE1: SPIRAL RO REJECT | FM1: CL 502 I/L | FT1: CL 502 O/L | GA1: UF FEED | GJ1: UF REJECT | GS1: UF PERMEATE | HB1: RO FEED | HI1: RO PERMEATE | HQ1: RO Reject | HY1: HP RO FEED | IF1: HP RO PERMEATE | IN1: HP RO Reject | IU1: T-512 | JC1: T-513 | JI1: SLUDGE SCP 502 SAMPLE | JJ1: Filtrate SCP 502 SAMPLE | JP1: Filtrate SCP 501 SAMPLE | JV1: SLUDGE SCP 501 SAMPLE | JW1: SCREW PRESS Filtrate
C2: Flow Rate | D2: pH | E2: Temperature | F2: TDS | G2: COD | H2: BOD | I2: TSS | J2: Turbidity | K2: NH4-N | L2: pH | M2: TDS | N2: COD | O2: NH4-N | P2: TH | Q2: EX.mg | R2: ex.po4 | S2: pH | T2: TDS | U2: COD | V2: BOD | W2: NH4-N | X2: Turbidity | Y2: TH | Z2: Calcium | AA2: Colour | AB2: pH | AC2: TDS | AD2: COD | AE2: Turbidity | AF2: NH4-N | AG2: Magnesium | AH2: Phosphate | AI2: pH | AJ2: TDS | AK2: COD | AL2: Turbidity | AM2: NH4-N | AN2: TH | AO2: Temperature | AP2: pH | AQ2: TDS | AR2: COD | AS2: BOD | AT2: TSS | AU2: Turbidity | AV2: NH4-N | AW2: TH | AX2: pH | AY2: TA | AZ2: TDS | BA2: COD | BB2: BOD | BC2: NH4-N | BD2: PO4 | BE2: DO | BF2: MLSS | BG2: MLVSS | BH2: MLVSS/MLSS Ratio | BI2: TH | BJ2: Temperature | BK2: pH | BL2: TA | BM2: TDS | BN2: COD | BO2: BOD | BP2: NH4-N | BQ2: TSS | BR2: Turbidity | BS2: MLSS | BT2: MLVSS | BU2: pH | BV2: TDS | BW2: COD | BX2: BOD | BY2: NH4-N | BZ2: DO | CA2: MLSS | CB2: MLVSS | CC2: pH | CD2: TDS | CE2: COD | CF2: BOD | CG2: NH4-N | CH2: DO | CI2: MLSS | CJ2: MLVSS | CK2: PO4 | CL2: pH | CM2: TSS | CN2: TDS | CO2: COD | CP2: BOD | CQ2: NH4-N | CR2: Turbidity | CS2: TH | CT2: pH | CU2: TDS | CV2: COD | CW2: BOD | CX2: TSS | CY2: NH4-N | CZ2: Turbidity | DA2: pH | DB2: TDS | DC2: COD | DD2: NH4-N | DE2: TSS | DF2: TH | DG2: BOD | DH2: Turbidity | DI2: pH | DJ2: TDS | DK2: COD | DL2: NH4-N | DM2: Turbidity | DN2: pH | DO2: TDS | DP2: COD | DQ2: NH4-N | DR2: TSS | DS2: MOISTURE | DT2: Calorific Value | DU2: Moisture | DX2: pH | DY2: TDS | DZ2: COD | EA2: BOD | EB2: NH4-N | EC2: TSS | ED2: Turbidity | EE2: TH | EF2: Colour | EG2: pH | EH2: TDS | EI2: COD | EJ2: BOD | EK2: NH4-N | EL2: TSS | EM2: Turbidity | EN2: TH | EO2: Colour | EP2: pH | EQ2: TDS | ER2: COD | ES2: NH4-N | ET2: TSS | EU2: TH | EV2: Colour | EW2: pH | EX2: TDS | EY2: COD | EZ2: BOD | FA2: NH4-N | FB2: TSS | FC2: TH | FD2: Colour | FE2: pH | FF2: TDS | FG2: COD | FH2: NH4-N | FI2: TSS | FJ2: TH | FK2: Turbidity | FL2: Colour | FM2: pH | FN2: TDS | FO2: COD | FP2: NH4-N | FQ2: TSS | FR2: TH | FS2: Turbidity | FT2: pH | FU2: TDS | FV2: COD | FW2: NH4-N | FX2: TSS | FY2: TH | FZ2: Turbidity | GA2: pH | GB2: TDS | GC2: COD | GD2: TURBIDITY | GE2: NH4-N | GF2: TSS | GG2: BOD | GH2: TH | GI2: Colour | GJ2: pH | GK2: TDS | GL2: COD | GM2: TURBIDITY | GN2: NH4-N | GO2: TSS | GP2: BOD | GQ2: TH | GR2: Colour | GS2: pH | GT2: TDS | GU2: COD | GV2: TURBIDITY | GW2: NH4-N | GX2: TSS | GY2: BOD | GZ2: TH | HA2: Colour | HB2: pH | HC2: TDS | HD2: COD | HE2: NH4-N | HF2: TSS | HG2: TH | HH2: Colour | HI2: pH | HJ2: TDS | HK2: COD | HL2: BOD | HM2: NH4-N | HN2: TSS | HO2: TH | HP2: Colour | HQ2: pH | HR2: TDS | HS2: COD | HT2: NH4-N | HU2: TSS | HV2: TH | HW2: Turbidity | HX2: Colour | HY2: pH | HZ2: TDS | IA2: COD | IB2: NH4-N | IC2: TSS | ID2: TH | IE2: Colour | IF2: pH | IG2: TDS | IH2: COD | II2: BOD | IJ2: NH4-N | IK2: TSS | IL2: TH | IM2: Colour | IN2: pH | IO2: TDS | IP2: COD | IQ2: NH4-N | IR2: TSS | IS2: TH | IT2: Colour | IU2: pH | IV2: TDS | IW2: COD | IX2: NH4-N | IY2: BOD | IZ2: TSS | JA2: Turbidity | JB2: TH | JC2: pH | JD2: TDS | JE2: COD | JF2: BOD | JG2: NH4-N | JH2: TH | JI2: Moisture | JJ2: pH | JK2: TDS | JL2: COD | JM2: NH4-N | JN2: TSS | JO2: Turbidity | JP2: pH | JQ2: TDS | JR2: COD | JS2: NH4-N | JT2: TSS | JU2: Turbidity | JV2: Moisture | JW2: pH | JX2: TDS | JY2: COD | JZ2: NH4-N | KA2: TSS | KB2: Turbidity
A3: 45658 | C3: 3.5 | D3: 7.67 | E3: 22.7 | F3: 742 | G3: 3491.5 | H3: 2400 | I3: 126 | J3: 38.1 | K3: 125 | Y3: 16 | Z3: 4 | AA3: 3067 | AO3: 22.7 | AP3: 6.48 | AQ3: 1016 | AR3: 3440.5 | AS3: 1950 | AT3: 84 | AU3: 29.7 | AV3: 121 | AW3: 101 | AX3: 6.5433333 | AY3: 343 | AZ3: 1523.3333 | BA3: 465.33333 | BB3: 135 | BC3: 127.66667 | BD3: 2 | BE3: 3.5 | BF3: 3986 | BG3: 2386 | BH3: 0.59 | BI3: 101 | BJ3: 24.166667 | BK3: 6.6966667 | BL3: 332 | BM3: 1575.6667 | BN3: 470.66667 | BO3: 105 | BP3: 197.66667 | BQ3: 6 | BR3: 5.1 | BS3: 4885 | BT3: 2935 | BU3: 7.2666667 | BV3: 1482.3333 | BW3: 458.66667 | BX3: 78 | BY3: 125.66667 | BZ3: 4.5 | CA3: 2658 | CB3: 1538 | CC3: 7.26 | CD3: 1475.3333 | CE3: 452.66667 | CF3: 72 | CG3: 125 | CH3: 5 | CI3: 2365 | CJ3: 1423 | CK3: 1.2433333 | CL3: 7.77 | CM3: 162 | CN3: 1434.5 | CO3: 470 | CP3: 48 | CQ3: 132.5 | CR3: 29.15 | CS3: 141 | CT3: 7.735 | CU3: 1387 | CV3: 466 | CW3: 42 | CX3: 132 | CY3: 130 | CZ3: 34.05 | DA3: 7.73 | DB3: 1432 | DC3: 474.5 | DD3: 134.5 | DE3: 106 | DF3: 118.5 | DG3: 40 | DH3: 31.3 | DX3: 7.525 | DY3: 1436.5 | DZ3: 466 | EA3: 33 | EB3: 127.5 | EC3: 118 | ED3: 26.4 | EE3: 135.5 | EF3: 2114.5 | EG3: 5.41 | EH3: 1463 | EI3: 437 | EJ3: 27 | EK3: 122 | EL3: 10 | EM3: 1.565 | EN3: 118 | EO3: 364.5 | EP3: 6.65 | EQ3: 1509 | ER3: 428 | ES3: 112 | ET3: 2 | EU3: 131 | EV3: 249 | EW3: 6.08 | EX3: 72.21 | EY3: 4 | EZ3: 2 | FA3: 7 | FB3: 2 | FC3: 4 | FD3: 10.715 | FE3: 7.26 | FF3: 4236 | FG3: 1713 | FH3: 509 | FI3: 16 | FJ3: 404 | FK3: 2.01 | FL3: 1840 | HY3: 7.17 | HZ3: 4263 | IA3: 1611 | IB3: 502 | IC3: 2 | ID3: 383 | IE3: 788 | IF3: 7.19 | IG3: 1448 | IH3: 228 | II3: 2 | IJ3: 93 | IK3: 2 | IL3: 66 | IM3: 82.632 | IN3: 7.48 | IO3: 12090 | IP3: 264 | IQ3: 844 | IR3: 6 | IS3: 844 | IT3: 750 | IU3: 6.105 | IV3: 1483.5 | IW3: 437.5 | IX3: 120.5 | IY3: 36 | IZ3: 4 | JA3: 1.16 | JB3: 149 | JC3: 6.395 | JD3: 73.58 | JE3: 16 | JF3: 2 | JG3: 6 | JH3: 5
A4: 45659 | C4: 3.5 | D4: 7.52 | E4: 22.95 | F4: 933.5 | G4: 3132 | H4: 2400 | I4: 72 | J4: 50.3 | K4: 105 | Y4: 20.5 | Z4: 4 | AA4: 3833 | AO4: 22.95 | AP4: 6.975 | AQ4: 1005 | AR4: 3488 | AS4: 1950 | AT4: 83 | AU4: 28 | AV4: 120.5 | AW4: 45 | AX4: 7.5066667 | AY4: 384 | AZ4: 1385 | BA4: 500 | BB4: 165 | BC4: 123.33333 | BD4: 2 | BE4: 3.7 | BF4: 6992 | BG4: 3896 | BH4: 0.55 | BI4: 80 | BJ4: 22.9 | BK4: 6.715 | BL4: 364 | BM4: 1371.5 | BN4: 517 | BO4: 105 | BP4: 126 | BQ4: 18 | BR4: 6.15 | BS4: 5865 | BT4: 3526 | BU4: 7.5333333 | BV4: 1379 | BW4: 494.33333 | BX4: 96 | BY4: 120.33333 | BZ4: 4.9 | CA4: 4852 | CB4: 3011 | CC4: 7.9966667 | CD4: 1404.6667 | CE4: 489.33333 | CF4: 78 | CG4: 118 | CH4: 5.2 | CI4: 3865 | CJ4: 2510 | CK4: 1 | CL4: 7.72 | CM4: 100 | CN4: 1320 | CO4: 498.5 | CP4: 48 | CQ4: 126 | CR4: 35.4 | CS4: 75 | CT4: 7.685 | CU4: 1341.5 | CV4: 492.5 | CW4: 39 | CX4: 98 | CY4: 124 | CZ4: 31.85 | DA4: 8 | DB4: 1364 | DC4: 490.5 | DD4: 127 | DE4: 29.7 | DF4: 88 | DG4: 39 | DH4: 74.55 | DX4: 7.75 | DY4: 1380 | DZ4: 453 | EA4: 24 | EB4: 119 | EC4: 130 | ED4: 29.9 | EE4: 115 | EF4: 3015 | EG4: 6.5 | EH4: 1395 | EI4: 449 | EJ4: 27 | EK4: 113 | EL4: 3 | EM4: 1.34 | EN4: 100 | EO4: 298 | EP4: 4.88 | EQ4: 1369 | ER4: 433 | ES4: 111 | ET4: 8 | EU4: 80 | EV4: 30 | EW4: 4.21 | EX4: 74.24 | EY4: 16 | EZ4: 2 | FA4: 5 | FB4: 2 | FC4: 8 | FD4: 10.35 | FE4: 5.17 | FF4: 5636 | FG4: 1598 | FH4: 174 | FI4: 12 | FJ4: 250 | FK4: 2.3 | FL4: 1138 | HY4: 5.64 | HZ4: 5625 | IA4: 1558 | IB4: 167 | IC4: 18 | ID4: 265 | IE4: 803 | IF4: 5.44 | IG4: 1170 | IH4: 137 | II4: 2 | IJ4: 55 | IK4: 2 | IL4: 52 | IM4: 78.352 | IN4: 6.71 | IO4: 8646 | IP4: 2064 | IQ4: 448 | IR4: 30 | IS4: 425 | IT4: 833 | IU4: 7.13 | IV4: 1376.5 | IW4: 456 | IX4: 115.5 | IY4: 29 | IZ4: 8 | JA4: 2.245 | JB4: 90.5 | JC4: 7.48 | JD4: 79.79 | JE4: 20 | JF4: 2 | JG4: 6 | JH4: 12
A5: 45660 | C5: 4 | D5: 7.52 | E5: 22.95 | F5: 933.5 | G5: 3132 | H5: 2400 | I5: 72 | J5: 50.3 | K5: 105 | Y5: 20.5 | Z5: 4 | AA5: 3833 | AO5: 22.95 | AP5: 6.975 | AQ5: 1005 | AR5: 3488 | AS5: 1950 | AT5: 83 | AU5: 28 | AV5: 120.5 | AW5: 45 | AX5: 7.5066667 | AY5: 384 | AZ5: 1385 | BA5: 500 | BB5: 150 | BC5: 123.33333 | BD5: 2 | BE5: 3.5 | BF5: 6992 | BG5: 3896 | BH5: 0.55 | BI5: 80 | BJ5: 22.9 | BK5: 6.715 | BL5: 364 | BM5: 1371.5 | BN5: 517 | BO5: 105 | BP5: 126 | BQ5: 18 | BR5: 6.15 | BS5: 5865 | BT5: 3526 | BU5: 7.5333333 | BV5: 1379 | BW5: 494.33333 | BX5: 84 | BY5: 120.33333 | BZ5: 3.8 | CA5: 4852 | CB5: 3011 | CC5: 7.9966667 | CD5: 1404.6667 | CE5: 489.33333 | CF5: 60 | CG5: 118 | CH5: 4.2 | CI5: 3865 | CJ5: 2510 | CK5: 1 | CL5: 7.72 | CM5: 100 | CN5: 1320 | CO5: 498.5 | CP5: 48 | CQ5: 126 | CR5: 35.4 | CS5: 75 | CT5: 7.685 | CU5: 1341.5 | CV5: 492.5 | CW5: 39 | CX5: 98 | CY5: 124 | CZ5: 31.85 | DA5: 8 | DB5: 1364 | DC5: 490.5 | DD5: 127 | DE5: 29.7 | DF5: 88 | DG5: 39 | DH5: 74.55 | DX5: 7.75 | DY5: 1380 | DZ5: 453 | EA5: 24 | EB5: 119 | EC5: 130 | ED5: 29.9 | EE5: 115 | EF5: 3015 | EG5: 6.5 | EH5: 1395 | EI5: 449 | EJ5: 27 | EK5: 113 | EL5: 3 | EM5: 1.34 | EN5: 100 | EO5: 298 | EP5: 4.88 | EQ5: 1369 | ER5: 433 | ES5: 111 | ET5: 8 | EU5: 80 | EV5: 30 | EW5: 4.21 | EX5: 74.24 | EY5: 16 | EZ5: 2 | FA5: 5 | FB5: 2 | FC5: 8 | FD5: 10.35 | FE5: 5.17 | FF5: 5636 | FG5: 1598 | FH5: 174 | FI5: 12 | FJ5: 250 | FK5: 2.3 | FL5: 1138 | HY5: 5.64 | HZ5: 5625 | IA5: 1558 | IB5: 167 | IC5: 18 | ID5: 265 | IE5: 803 | IF5: 5.44 | IG5: 1170 | IH5: 137 | II5: 2 | IJ5: 55 | IK5: 2 | IL5: 52 | IM5: 78.352 | IN5: 6.71 | IO5: 8646 | IP5: 2064 | IQ5: 448 | IR5: 30 | IS5: 425 | IT5: 833 | IU5: 7.13 | IV5: 1376.5 | IW5: 456 | IX5: 115.5 | IY5: 27 | IZ5: 8 | JA5: 2.245 | JB5: 90.5 | JC5: 7.48 | JD5: 79.79 | JE5: 20 | JF5: 2 | JG5: 6 | JH5: 12
A6: 45661 | C6: 5.17 | D6: 8.7333333 | E6: 23.433333 | F6: 720.66667 | G6: 2665 | I6: 38 | J6: 40.766667 | K6: 98 | Y6: 18 | Z6: 4 | AA6: 2940 | AO6: 23.3 | AP6: 7.3633333 | AQ6: 1270.3333 | AR6: 2604 | AT6: 28 | AU6: 43.7 | AV6: 97.333333 | AW6: 110 | AX6: 7.12 | AY6: 364 | AZ6: 1802 | BA6: 445.66667 | BC6: 165 | BD6: 1.9533333 | BE6: 3.8 | BF6: 2498 | BG6: 1514 | BH6: 0.61 | BI6: 120 | BJ6: 23.366667 | BK6: 6.5833333 | BL6: 333 | BM6: 1801.3333 | BN6: 455 | BP6: 166.66667 | BQ6: 26 | BR6: 3.1 | BS6: 5046 | BT6: 3128 | BU6: 7.59 | BV6: 1723.6667 | BW6: 436 | BY6: 164.66667 | BZ6: 4.2 | CA6: 2791 | CB6: 1415 | CC6: 7.44 | CD6: 1723 | CE6: 432 | CG6: 162.66667 | CH6: 5.1 | CI6: 4164 | CJ6: 2478 | CK6: 1.4233333 | CL6: 7.5766667 | CM6: 46 | CN6: 1717.3333 | CO6: 433.33333 | CQ6: 166.66667 | CR6: 5.0333333 | CS6: 170 | CT6: 7.52 | CU6: 1703 | CV6: 429.33333 | CX6: 40 | CY6: 166.66667 | CZ6: 4.7666667 | DA6: 7.8466667 | DB6: 1658.3333 | DC6: 439.66667 | DD6: 166.33333 | DE6: 52 | DF6: 141.66667 | DH6: 12.833333 | DX6: 7.77 | DY6: 1639.6667 | DZ6: 429.33333 | EA6: 25 | EB6: 164 | EC6: 46 | ED6: 10.833333 | EE6: 148.33333 | EF6: 2854 | EG6: 7.8466667 | EH6: 1609 | EI6: 386 | EK6: 150 | EM6: 1.4333333 | EN6: 125 | EO6: 540 | EP6: 7.0366667 | EQ6: 1666 | ER6: 375 | ES6: 148.66667 | ET6: 4 | EU6: 131.66667 | EV6: 385.33333 | EW6: 6.92 | EX6: 70.6 | EY6: 18.666667 | EZ6: 4 | FA6: 4.6666667 | FB6: 2 | FC6: 7.6666667 | FD6: 11.49 | FE6: 6.9666667 | FF6: 5746 | FG6: 1494 | FH6: 422 | FI6: 18 | FJ6: 460.33333 | FK6: 2.15 | FL6: 1394.3333 | HY6: 6.8966667 | HZ6: 5645.6667 | IA6: 1419.3333 | IB6: 416.33333 | IC6: 16 | ID6: 427 | IE6: 1328.6667 | IF6: 8.6033333 | IG6: 495.56667 | IH6: 67.666667 | IJ6: 28.333333 | IL6: 17.333333 | IM6: 48.906667 | IN6: 7.86 | IO6: 7912 | IP6: 2240.6667 | IQ6: 550 | IR6: 34 | IS6: 590.33333 | IT6: 1511.3333 | IU6: 7.8533333 | IV6: 1609.3333 | IW6: 389.66667 | IX6: 147.33333 | IZ6: 8 | JA6: 1.13 | JB6: 121.66667 | JC6: 6.6633333 | JD6: 71.216667 | JE6: 20.333333 | JG6: 4.3333333 | JH6: 8.3333333 | JI6: 82.21 | JJ6: 6.67 | JK6: 1750 | JL6: 410 | JM6: 157 | JO6: 82.21
A7: 45662 | C7: 4.26 | D7: 8.5266667 | E7: 23 | F7: 1082.3333 | G7: 3331 | I7: 70 | J7: 55.966667 | K7: 112.66667 | Y7: 111.33333 | Z7: 36 | AA7: 2163 | AO7: 22.9 | AP7: 7.3133333 | AQ7: 1472 | AR7: 3263 | AT7: 98 | AU7: 62.3 | AV7: 111.33333 | AW7: 140 | AX7: 6.9766667 | AY7: 211 | AZ7: 1632.3333 | BA7: 413.33333 | BC7: 129.33333 | BD7: 2.4633333 | BE7: 2.5 | BF7: 3896 | BG7: 2355 | BH7: 0.6 | BI7: 150 | BJ7: 23.133333 | BK7: 6.6633333 | BL7: 189 | BM7: 1696.3333 | BN7: 419 | BP7: 131 | BQ7: 14 | BR7: 3.3 | BS7: 5862 | BT7: 3065 | BU7: 7.5233333 | BV7: 1669.6667 | BW7: 401.33333 | BY7: 127 | BZ7: 4 | CA7: 3521 | CB7: 1865 | CC7: 7.6266667 | CD7: 1901 | CE7: 395.66667 | CG7: 125 | CH7: 5.3 | CI7: 3265 | CJ7: 1723 | CK7: 1.6666667 | CL7: 7.8833333 | CM7: 38 | CN7: 1662.3333 | CO7: 412 | CQ7: 136.66667 | CR7: 12.24 | CS7: 100 | CT7: 7.8966667 | CU7: 1660.6667 | CV7: 406.66667 | CX7: 40 | CY7: 133 | CZ7: 12.133333 | DA7: 7.9366667 | DB7: 1636.3333 | DC7: 416 | DD7: 133.66667 | DE7: 24 | DF7: 126.66667 | DH7: 12.766667 | DX7: 7.95 | DY7: 1638.6667 | DZ7: 412 | EB7: 130 | EC7: 39 | ED7: 11.733333 | EE7: 136.66667 | EF7: 917.66667 | EG7: 8.13 | EH7: 1745.6667 | EI7: 379.66667 | EK7: 117.33333 | EL7: 3 | EM7: 0.70333333 | EN7: 110 | EO7: 464.66667 | EP7: 7.79 | EQ7: 1626.6667 | ER7: 371.66667 | ES7: 115.33333 | EU7: 86.666667 | EV7: 569.66667 | EW7: 6.6766667 | EX7: 62.986667 | EY7: 20 | EZ7: 3 | FA7: 4.3333333 | FB7: 2 | FC7: 4.6666667 | FD7: 11.479 | FE7: 7.0766667 | FF7: 6268.3333 | FG7: 1341.6667 | FH7: 370 | FI7: 13 | FJ7: 320.33333 | FK7: 9.3533333 | FL7: 1660.3333 | HB7: 7.575 | HC7: 5709.5 | HD7: 1503 | HE7: 556.5 | HF7: 22 | HG7: 375.5 | HH7: 2033 | HI7: 7.035 | HJ7: 1845.5 | HK7: 289 | HL7: 2 | HM7: 139 | HN7: 2 | HO7: 69 | HP7: 455 | HQ7: 6.945 | HR7: 9449.5 | HS7: 2436.5 | HT7: 864 | HU7: 36 | HV7: 570.5 | HX7: 1574 | HY7: 7.04 | HZ7: 4623 | IA7: 1672 | IB7: 295 | IC7: 14 | ID7: 320 | IE7: 562 | IF7: 7.17 | IG7: 877.6 | IH7: 102 | IJ7: 34 | IL7: 320 | IM7: 562 | IN7: 7.45 | IO7: 11600 | IP7: 2244 | IQ7: 708 | IR7: 15 | IS7: 708 | IT7: 1283 | IU7: 8.0966667 | IV7: 1613.3333 | IW7: 375.66667 | IX7: 115.66667 | IZ7: 10 | JA7: 0.88 | JB7: 100 | JC7: 7.21 | JD7: 93.05 | JE7: 29.666667 | JG7: 4.6666667 | JH7: 6.3333333 | JI7: 86.35 | JJ7: 8.08 | JK7: 2418 | JL7: 775 | JM7: 125 | JN7: 34 | JO7: 3.7
A8: 45663 | C8: 5.75 | D8: 9.0533333 | E8: 23.266667 | F8: 786 | G8: 3562 | I8: 154 | J8: 21.9 | K8: 136.66667 | Y8: 66.666667 | Z8: 32 | AA8: 1745 | AO8: 23.266667 | AP8: 7.77 | AQ8: 1590.3333 | AR8: 3483.6667 | AT8: 26 | AU8: 30.2 | AV8: 134.33333 | AW8: 115 | AX8: 6.4566667 | AY8: 208 | AZ8: 1554.3333 | BA8: 399.33333 | BC8: 148.33333 | BD8: 2.4463333 | BE8: 2.4 | BF8: 8965 | BG8: 5326 | BH8: 0.59 | BI8: 150 | BJ8: 23.366667 | BK8: 6.1666667 | BL8: 187 | BM8: 1619 | BN8: 400.66667 | BP8: 118.66667 | BQ8: 26 | BR8: 3.3666667 | BS8: 9653 | BT8: 5862 | BU8: 6.7533333 | BV8: 1593.3333 | BW8: 394 | BY8: 115.33333 | BZ8: 5 | CA8: 3895 | CB8: 2356 | CC8: 7.1266667 | CD8: 1578.3333 | CE8: 387.33333 | CG8: 113.66667 | CH8: 5.5 | CI8: 3585 | CJ8: 2156 | CK8: 1.9703333 | CL8: 7.4633333 | CM8: 112 | CN8: 1609.6667 | CO8: 396.66667 | CQ8: 117.33333 | CR8: 9.3333333 | CS8: 140 | CT8: 7.5233333 | CU8: 1779.3333 | CV8: 392.66667 | CX8: 72 | CY8: 115.33333 | CZ8: 8.0666667 | DA8: 261.64 | DB8: 1538 | DC8: 392.66667 | DD8: 117 | DE8: 68 | DF8: 160 | DH8: 7.5333333 | DX8: 7.72 | DY8: 1535.3333 | DZ8: 392.66667 | EB8: 118 | EC8: 49 | ED8: 8.2 | EE8: 165 | EF8: 1111.3333 | EG8: 7.6933333 | EH8: 1569.3333 | EI8: 372.66667 | EK8: 111.33333 | EL8: 4 | EM8: 0.65 | EN8: 153.33333 | EO8: 390.16667 | EP8: 7.0433333 | EQ8: 1599.3333 | ER8: 366.66667 | ES8: 109 | ET8: 6 | EU8: 151.66667 | EV8: 382.33333 | EW8: 6.8033333 | EX8: 70.043333 | EY8: 18.666667 | FA8: 6.6666667 | FB8: 2 | FC8: 4 | FD8: 6.3846667 | FE8: 6.95 | FF8: 5770 | FG8: 1280.6667 | FH8: 419.66667 | FI8: 8 | FJ8: 450 | FK8: 0.85666667 | FL8: 562.66667 | HB8: 7.465 | HC8: 5021.5 | HD8: 1186.5 | HE8: 396 | HF8: 22 | HG8: 480 | HH8: 527 | HI8: 7.655 | HJ8: 1464 | HK8: 124 | HL8: 2 | HM8: 44.5 | HN8: 2 | HO8: 42 | HP8: 142 | HQ8: 7.41 | HR8: 9701 | HS8: 1591.5 | HT8: 602 | HU8: 24 | HV8: 1295 | HX8: 885 | HY8: 7.1 | HZ8: 5575 | IA8: 1128 | IB8: 277 | ID8: 410 | IE8: 526 | IF8: 7.32 | IG8: 1012 | IH8: 88 | IJ8: 25 | IL8: 38 | IM8: 126 | IN8: 7.17 | IO8: 7890 | IP8: 1673 | IQ8: 414 | IR8: 20 | IS8: 810 | IT8: 782 | IU8: 7.8133333 | IV8: 1602.3333 | IW8: 368 | IX8: 109.33333 | IZ8: 12 | JA8: 0.82333333 | JB8: 156.66667 | JC8: 6.8566667 | JD8: 62.24 | JE8: 20 | JG8: 7.6666667 | JH8: 5 | JI8: 88.77 | JJ8: 5.75 | JK8: 2288 | JL8: 416 | JM8: 115 | JN8: 8 | JO8: 6.7
A9: 45664
A10: 45665
A11: 45666
A12: 45667
A13: 45668
A14: 45669
A15: 45670
A16: 45671
A17: 45672
A18: 45673
A19: 45674
A20: 45675
... A33: 45688
A35: Maximum | C35: =MAX(C3:C33) -> 5.75 | D35: =MAX(D3:D33) -> 9.0533333 | E35: =MAX(E3:E33) -> 23.433333 | F35: =MAX(F3:F33) -> 1082.3333 | G35: =MAX(G3:G33) -> 3562 | H35: =MAX(H3:H33) -> 2400 | I35: =MAX(I3:I33) -> 154 | J35: =MAX(J3:J33) -> 55.966667 | ... KB35: =MAX(KB3:KB33) -> 0
A36: Minimum | C36: =MIN(C3:C33) -> 3.5 | D36: =MIN(D3:D33) -> 7.52 | E36: =MIN(E3:E33) -> 22.7 | F36: =MIN(F3:F33) -> 720.66667 | G36: =MIN(G3:G33) -> 2665 | H36: =MIN(H3:H33) -> 2400 | I36: =MIN(I3:I33) -> 38 | J36: =MIN(J3:J33) -> 21.9 | ... KB36: =MIN(KB3:KB33) -> 0
A37: Average | C37: =AVERAGE(C3:C33) -> 4.3633333 | D37: =AVERAGE(D3:D33) -> 8.1705556 | E37: =AVERAGE(E3:E33) -> 23.05 | F37: =AVERAGE(F3:F33) -> 866.33333 | G37: =AVERAGE(G3:G33) -> 3218.9167 | H37: =AVERAGE(H3:H33) -> 2400 | I37: =AVERAGE(I3:I33) -> 88.666667 | J37: =AVERAGE(J3:J33) -> 42.888889 | ... KB37: =AVERAGE(KB3:KB33) -> #DIV/0!

Sheet Dashboard (Daily Analysis)

Sheet Analysis Sheet 1
A1: Stages | B1: Parameter | C1: Maximum | D1: Minimum | E1: Average | M1: Parameter | N1: Stages
A2: ZLD Plant (I/L) | B2: Flow Rate | C2: ='Report Book'!C35 -> 5.75 | D2: ='Report Book'!C36 -> 3.5 | E2: ='Report Book'!C37 -> 4.3633333 | M2: Flow Rate | N2: ZLD Plant (I/L)
A3: ZLD Plant (I/L) | B3: pH | C3: ='Report Book'!D35 -> 9.0533333 | D3: ='Report Book'!D36 -> 7.52 | E3: ='Report Book'!D37 -> 8.1705556 | M3: pH | N3: ASP (I/L)
A4: ZLD Plant (I/L) | B4: Temperature | C4: ='Report Book'!E35 -> 23.433333 | D4: ='Report Book'!E36 -> 22.7 | E4: ='Report Book'!E37 -> 23.05 | M4: Temperature | N4: ASP (T-501)
A5: ZLD Plant (I/L) | B5: TDS | C5: ='Report Book'!F35 -> 1082.3333 | D5: ='Report Book'!F36 -> 720.66667 | E5: ='Report Book'!F37 -> 866.33333 | M5: TDS | N5: SC (O/F)
A6: ZLD Plant (I/L) | B6: COD | C6: ='Report Book'!G35 -> 3562 | D6: ='Report Book'!G36 -> 2665 | E6: ='Report Book'!G37 -> 3218.9167 | M6: COD | N6: SC (U/F)
A7: ZLD Plant (I/L) | B7: BOD | C7: ='Report Book'!H35 -> 2400 | D7: ='Report Book'!H36 -> 2400 | E7: ='Report Book'!H37 -> 2400 | M7: BOD | N7: MBBR I
A8: ZLD Plant (I/L) | B8: TSS | C8: ='Report Book'!I35 -> 154 | D8: ='Report Book'!I36 -> 38 | E8: ='Report Book'!I37 -> 88.666667 | M8: TSS | N8: MBBR II
A9: ZLD Plant (I/L) | B9: Turbidity | C9: ='Report Book'!J35 -> 55.966667 | D9: ='Report Book'!J36 -> 21.9 | E9: ='Report Book'!J37 -> 42.888889 | M9: Turbidity | N9: TS-502 (O/F)
A10: ZLD Plant (I/L) | B10: NH4-N | C10: ='Report Book'!K35 -> 136.66667 | D10: ='Report Book'!K36 -> 98 | E10: ='Report Book'!K37 -> 113.72222 | M10: NH4-N | N10: GSF (O/L)
A11: ZLD Plant (I/L) | B11: TH | C11: ='Report Book'!Y35 -> 111.33333 | D11: ='Report Book'!Y36 -> 16 | E11: ='Report Book'!Y37 -> 42.166667 | M11: TH | N11: MBR (I/L)
A12: ZLD Plant (I/L) | B12: Calcium | C12: ='Report Book'!Z35 -> 36 | D12: ='Report Book'!Z36 -> 4 | E12: ='Report Book'!Z37 -> 14 | M12: Calcium | N12: MBR (O/L)
A13: ZLD Plant (I/L) | B13: Colour | C13: ='Report Book'!AA35 -> 3833 | D13: ='Report Book'!AA36 -> 1745 | E13: ='Report Book'!AA37 -> 2930.1667 | M13: Colour | N13: SPRO (Feed)
A14: ASP (I/L) | B14: Temperature | C14: ='Report Book'!AO35 -> 23.3 | D14: ='Report Book'!AO36 -> 22.7 | E14: ='Report Book'!AO37 -> 23.011111 | M14: Temp. | N14: SPRO (Permeate)
A15: ASP (I/L) | B15: pH | C15: ='Report Book'!AP35 -> 7.77 | D15: ='Report Book'!AP36 -> 6.48 | E15: ='Report Book'!AP37 -> 7.1461111 | M15: TA | N15: SPRO (Reject)
A16: ASP (I/L) | B16: TDS | C16: ='Report Book'!AQ35 -> 1590.3333 | D16: ='Report Book'!AQ36 -> 1005 | E16: ='Report Book'!AQ37 -> 1226.4444 | M16: PO4 | N16: PTRO (Feed)
A17: ASP (I/L) | B17: COD | C17: ='Report Book'!AR35 -> 3488 | D17: ='Report Book'!AR36 -> 2604 | E17: ='Report Book'!AR37 -> 3294.5278 | M17: DO | N17: PTRO (Permeate)
A18: ASP (I/L) | B18: BOD | C18: ='Report Book'!AS35 -> 1950 | D18: ='Report Book'!AS36 -> 1950 | E18: ='Report Book'!AS37 -> 1950 | M18: MLSS | N18: PTRO (Reject)
A19: ASP (I/L) | B19: TSS | C19: ='Report Book'!AT35 -> 98 | D19: ='Report Book'!AT36 -> 26 | E19: ='Report Book'!AT37 -> 67 | M19: MLVSS | N19: HPRO (Feed)
A20: ASP (I/L) | B20: Turbidity | C20: ='Report Book'!AU35 -> 62.3 | D20: ='Report Book'!AU36 -> 28 | E20: ='Report Book'!AU37 -> 36.983333 | M20: Ratio | N20: HPRO (Permeate)
A21: ASP (I/L) | B21: NH4-N | C21: ='Report Book'!AV35 -> 134.33333 | D21: ='Report Book'!AV36 -> 97.333333 | E21: ='Report Book'!AV37 -> 117.5 | N21: HPRO (Reject)
A22: ASP (I/L) | B22: TH | C22: ='Report Book'!AW35 -> 140 | D22: ='Report Book'!AW36 -> 45 | E22: ='Report Book'!AW37 -> 92.666667
A23: ASP (T-501) | B23: pH | C23: ='Report Book'!AX35 -> 7.5066667 | D23: ='Report Book'!AX36 -> 6.4566667 | E23: ='Report Book'!AX37 -> 7.0183333
A24: ASP (T-501) | B24: TA | C24: ='Report Book'!AY35 -> 384 | D24: ='Report Book'!AY36 -> 208 | E24: ='Report Book'!AY37 -> 315.66667
A25: ASP (T-501) | B25: TDS | C25: ='Report Book'!AZ35 -> 1802 | D25: ='Report Book'!AZ36 -> 1385 | E25: ='Report Book'!AZ37 -> 1547
A26: ASP (T-501) | B26: COD | C26: ='Report Book'!BA35 -> 500 | D26: ='Report Book'!BA36 -> 399.33333 | E26: ='Report Book'!BA37 -> 453.94444
A27: ASP (T-501) | B27: BOD | C27: ='Report Book'!BB35 -> 165 | D27: ='Report Book'!BB36 -> 135 | E27: ='Report Book'!BB37 -> 150
A28: ASP (T-501) | B28: NH4-N | C28: ='Report Book'!BC35 -> 165 | D28: ='Report Book'!BC36 -> 123.33333 | E28: ='Report Book'!BC37 -> 136.16667
A29: ASP (T-501) | B29: PO4 | C29: ='Report Book'!BD35 -> 2.4633333 | D29: ='Report Book'!BD36 -> 1.9533333 | E29: ='Report Book'!BD37 -> 2.1438333
A30: ASP (T-501) | B30: DO | C30: ='Report Book'!BE35 -> 3.8 | D30: ='Report Book'!BE36 -> 2.4 | E30: ='Report Book'!BE37 -> 3.2333333
A31: ASP (T-501) | B31: MLSS | C31: ='Report Book'!BF35 -> 8965 | D31: ='Report Book'!BF36 -> 2498 | E31: ='Report Book'!BF37 -> 5554.8333
A32: ASP (T-501) | B32: MLVSS | C32: ='Report Book'!BG35 -> 5326 | D32: ='Report Book'!BG36 -> 1514 | E32: ='Report Book'!BG37 -> 3228.8333
A33: ASP (T-501) | B33: Ratio | C33: =C32/C31 -> 0.59408812 | D33: =D32/D31 -> 0.60608487 | E33: =E32/E31 -> 0.58126556
A34: ASP (T-501) | B34: TH | C34: ='Report Book'!BI35 -> 150 | D34: ='Report Book'!BI36 -> 80 | E34: ='Report Book'!BI37 -> 113.5
A35: SC (O/F) | B35: Temperature | C35: ='Report Book'!BJ35 -> 24.166667 | D35: ='Report Book'!BJ36 -> 22.9 | E35: ='Report Book'!BJ37 -> 23.305556
A36: SC (O/F) | B36: pH | C36: ='Report Book'!BK35 -> 6.715 | D36: ='Report Book'!BK36 -> 6.1666667 | E36: ='Report Book'!BK37 -> 6.59
A37: SC (O/F) | B37: TA | C37: ='Report Book'!BL35 -> 364 | D37: ='Report Book'!BL36 -> 187 | E37: ='Report Book'!BL37 -> 294.83333
A38: SC (O/F) | B38: TDS | C38: ='Report Book'!BM35 -> 1801.3333 | D38: ='Report Book'!BM36 -> 1371.5 | E38: ='Report Book'!BM37 -> 1572.5556
A39: SC (O/F) | B39: COD | C39: ='Report Book'!BN35 -> 517 | D39: ='Report Book'!BN36 -> 400.66667 | E39: ='Report Book'!BN37 -> 463.22222
A40: SC (O/F) | B40: BOD | C40: ='Report Book'!BO35 -> 105 | D40: ='Report Book'!BO36 -> 105 | E40: ='Report Book'!BO37 -> 105
...

Sheet Analysis Sheet 2
A1: Stages | B1: Parameter | C1: Maximum | D1: Minimum | E1: Average | M1: Parameter | N1: Stages
A2: ZLD Plant (I/L) | B2: Flow Rate | C2: ='Report Book'!C35 -> 5.75 | D2: ='Report Book'!C36 -> 3.5 | E2: ='Report Book'!C37 -> 4.3633333 | M2: Flow Rate | N2: ZLD Plant (I/L)
A3: ZLD Plant (I/L) | B3: pH | C3: ='Report Book'!D35 -> 9.0533333 | D3: ='Report Book'!D36 -> 7.52 | E3: ='Report Book'!D37 -> 8.1705556 | M3: pH | N3: ASP (I/L)
A4: ZLD Plant (I/L) | B4: Temperature | C4: ='Report Book'!E35 -> 23.433333 | D4: ='Report Book'!E36 -> 22.7 | E4: ='Report Book'!E37 -> 23.05 | M4: Temperature | N4: ASP (T-501)
A5: ZLD Plant (I/L) | B5: TDS | C5: ='Report Book'!F35 -> 1082.3333 | D5: ='Report Book'!F36 -> 720.66667 | E5: ='Report Book'!F37 -> 866.33333 | M5: TDS | N5: SC (O/F)
A6: ZLD Plant (I/L) | B6: COD | C6: ='Report Book'!G35 -> 3562 | D6: ='Report Book'!G36 -> 2665 | E6: ='Report Book'!G37 -> 3218.9167 | M6: COD | N6: SC (U/F)
A7: ZLD Plant (I/L) | B7: BOD | C7: ='Report Book'!H35 -> 2400 | D7: ='Report Book'!H36 -> 2400 | E7: ='Report Book'!H37 -> 2400 | M7: BOD | N7: MBBR I
A8: ZLD Plant (I/L) | B8: TSS | C8: ='Report Book'!I35 -> 154 | D8: ='Report Book'!I36 -> 38 | E8: ='Report Book'!I37 -> 88.666667 | M8: TSS | N8: MBBR II
A9: ZLD Plant (I/L) | B9: Turbidity | C9: ='Report Book'!J35 -> 55.966667 | D9: ='Report Book'!J36 -> 21.9 | E9: ='Report Book'!J37 -> 42.888889 | M9: Turbidity | N9: TS-502 (O/F)
A10: ZLD Plant (I/L) | B10: NH4-N | C10: ='Report Book'!K35 -> 136.66667 | D10: ='Report Book'!K36 -> 98 | E10: ='Report Book'!K37 -> 113.72222 | M10: NH4-N | N10: GSF (O/L)
A11: ZLD Plant (I/L) | B11: TH | C11: ='Report Book'!Y35 -> 111.33333 | D11: ='Report Book'!Y36 -> 16 | E11: ='Report Book'!Y37 -> 42.166667 | M11: TH | N11: MBR (I/L)
A12: ZLD Plant (I/L) | B12: Calcium | C12: ='Report Book'!Z35 -> 36 | D12: ='Report Book'!Z36 -> 4 | E12: ='Report Book'!Z37 -> 14 | M12: Calcium | N12: MBR (O/L)
A13: ZLD Plant (I/L) | B13: Colour | C13: ='Report Book'!AA35 -> 3833 | D13: ='Report Book'!AA36 -> 1745 | E13: ='Report Book'!AA37 -> 2930.1667 | M13: Colour | N13: SPRO (Feed)
A14: ASP (I/L) | B14: Temperature | C14: ='Report Book'!AO35 -> 23.3 | D14: ='Report Book'!AO36 -> 22.7 | E14: ='Report Book'!AO37 -> 23.011111 | M14: Temp. | N14: SPRO (Permeate)
A15: ASP (I/L) | B15: pH | C15: ='Report Book'!AP35 -> 7.77 | D15: ='Report Book'!AP36 -> 6.48 | E15: ='Report Book'!AP37 -> 7.1461111 | M15: TA | N15: SPRO (Reject)
A16: ASP (I/L) | B16: TDS | C16: ='Report Book'!AQ35 -> 1590.3333 | D16: ='Report Book'!AQ36 -> 1005 | E16: ='Report Book'!AQ37 -> 1226.4444 | M16: PO4 | N16: PTRO (Feed)
A17: ASP (I/L) | B17: COD | C17: ='Report Book'!AR35 -> 3488 | D17: ='Report Book'!AR36 -> 2604 | E17: ='Report Book'!AR37 -> 3294.5278 | M17: DO | N17: PTRO (Permeate)
A18: ASP (I/L) | B18: BOD | C18: ='Report Book'!AS35 -> 1950 | D18: ='Report Book'!AS36 -> 1950 | E18: ='Report Book'!AS37 -> 1950 | M18: MLSS | N18: PTRO (Reject)
A19: ASP (I/L) | B19: TSS | C19: ='Report Book'!AT35 -> 98 | D19: ='Report Book'!AT36 -> 26 | E19: ='Report Book'!AT37 -> 67 | M19: MLVSS | N19: HPRO (Feed)
A20: ASP (I/L) | B20: Turbidity | C20: ='Report Book'!AU35 -> 62.3 | D20: ='Report Book'!AU36 -> 28 | E20: ='Report Book'!AU37 -> 36.983333 | M20: Ratio | N20: HPRO (Permeate)
A21: ASP (I/L) | B21: NH4-N | C21: ='Report Book'!AV35 -> 134.33333 | D21: ='Report Book'!AV36 -> 97.333333 | E21: ='Report Book'!AV37 -> 117.5 | N21: HPRO (Reject)
A22: ASP (I/L) | B22: TH | C22: ='Report Book'!AW35 -> 140 | D22: ='Report Book'!AW36 -> 45 | E22: ='Report Book'!AW37 -> 92.666667
A23: ASP (T-501) | B23: pH | C23: ='Report Book'!AX35 -> 7.5066667 | D23: ='Report Book'!AX36 -> 6.4566667 | E23: ='Report Book'!AX37 -> 7.0183333
A24: ASP (T-501) | B24: TA | C24: ='Report Book'!AY35 -> 384 | D24: ='Report Book'!AY36 -> 208 | E24: ='Report Book'!AY37 -> 315.66667
A25: ASP (T-501) | B25: TDS | C25: ='Report Book'!AZ35 -> 1802 | D25: ='Report Book'!AZ36 -> 1385 | E25: ='Report Book'!AZ37 -> 1547
A26: ASP (T-501) | B26: COD | C26: ='Report Book'!BA35 -> 500 | D26: ='Report Book'!BA36 -> 399.33333 | E26: ='Report Book'!BA37 -> 453.94444
A27: ASP (T-501) | B27: BOD | C27: ='Report Book'!BB35 -> 165 | D27: ='Report Book'!BB36 -> 135 | E27: ='Report Book'!BB37 -> 150
A28: ASP (T-501) | B28: NH4-N | C28: ='Report Book'!BC35 -> 165 | D28: ='Report Book'!BC36 -> 123.33333 | E28: ='Report Book'!BC37 -> 136.16667
A29: ASP (T-501) | B29: PO4 | C29: ='Report Book'!BD35 -> 2.4633333 | D29: ='Report Book'!BD36 -> 1.9533333 | E29: ='Report Book'!BD37 -> 2.1438333
A30: ASP (T-501) | B30: DO | C30: ='Report Book'!BE35 -> 3.8 | D30: ='Report Book'!BE36 -> 2.4 | E30: ='Report Book'!BE37 -> 3.2333333
A31: ASP (T-501) | B31: MLSS | C31: ='Report Book'!BF35 -> 8965 | D31: ='Report Book'!BF36 -> 2498 | E31: ='Report Book'!BF37 -> 5554.8333
A32: ASP (T-501) | B32: MLVSS | C32: ='Report Book'!BG35 -> 5326 | D32: ='Report Book'!BG36 -> 1514 | E32: ='Report Book'!BG37 -> 3228.8333
A33: ASP (T-501) | B33: Ratio | C33: =C32/C31 -> 0.59408812 | D33: =D32/D31 -> 0.60608487 | E33: =E32/E31 -> 0.58126556
A34: ASP (T-501) | B34: TH | C34: ='Report Book'!BI35 -> 150 | D34: ='Report Book'!BI36 -> 80 | E34: ='Report Book'!BI37 -> 113.5
A35: SC (O/F) | B35: Temperature | C35: ='Report Book'!BJ35 -> 24.166667 | D35: ='Report Book'!BJ36 -> 22.9 | E35: ='Report Book'!BJ37 -> 23.305556
A36: SC (O/F) | B36: pH | C36: ='Report Book'!BK35 -> 6.715 | D36: ='Report Book'!BK36 -> 6.1666667 | E36: ='Report Book'!BK37 -> 6.59
A37: SC (O/F) | B37: TA | C37: ='Report Book'!BL35 -> 364 | D37: ='Report Book'!BL36 -> 187 | E37: ='Report Book'!BL37 -> 294.83333
A38: SC (O/F) | B38: TDS | C38: ='Report Book'!BM35 -> 1801.3333 | D38: ='Report Book'!BM36 -> 1371.5 | E38: ='Report Book'!BM37 -> 1572.5556
A39: SC (O/F) | B39: COD | C39: ='Report Book'!BN35 -> 517 | D39: ='Report Book'!BN36 -> 400.66667 | E39: ='Report Book'!BN37 -> 463.22222
A40: SC (O/F) | B40: BOD | C40: ='Report Book'!BO35 -> 105 | D40: ='Report Book'!BO36 -> 105 | E40: ='Report Book'!BO37 -> 105
...

Sheet Parameter (Wise)
A1: Stages | B1: Parameters | C1: Average
A2: ZLD Plant (I/L) | B2: Flow Rate | C2: 5.5757143
A3: ZLD Plant (I/L) | B3: pH | C3: 8.5781667
A4: ZLD Plant (I/L) | B4: Temp. | C4: 24.721889
A5: ZLD Plant (I/L) | B5: TDS | C5: 941.07889
A6: ZLD Plant (I/L) | B6: COD | C6: 4420.45
A7: ZLD Plant (I/L) | B7: BOD | C7: 2613.0769
A8: ZLD Plant (I/L) | B8: TSS | C8: 74.931034
A9: ZLD Plant (I/L) | B9: Turbidity | C9: 20.424333
A10: ZLD Plant (I/L) | B10: NH4-N | C10: 190.3
A11: ZLD Plant (I/L) | B11: TH | C11: 193.28889
A12: ZLD Plant (I/L) | B12: Calcium | C12: 44.396552
A13: ZLD Plant (I/L) | B13: Colour | C13: 1970.9655
... A148: T-513 | B148: TH | C148: 12.744444

Sheet Stages (Wise)
A1: Stages | B1: Parameters | C1: Average
A2: ZLD Plant (I/L) | B2: Flow Rate | C2: 5.5757143
A3: ZLD Plant (I/L) | B3: pH | C3: 8.5781667
A4: ZLD Plant (I/L) | B4: Temp. | C4: 24.721889
A5: ZLD Plant (I/L) | B5: TDS | C5: 941.07889
A6: ZLD Plant (I/L) | B6: COD | C6: 4420.45
A7: ZLD Plant (I/L) | B7: BOD | C7: 2613.0769
A8: ZLD Plant (I/L) | B8: TSS | C8: 74.931034
A9: ZLD Plant (I/L) | B9: Turbidity | C9: 20.424333
A10: ZLD Plant (I/L) | B10: NH4-N | C10: 190.3
A11: ZLD Plant (I/L) | B11: TH | C11: 193.28889
A12: ZLD Plant (I/L) | B12: Calcium | C12: 44.396552
A13: ZLD Plant (I/L) | B13: Colour | C13: 1970.9655
... A148: T-513 | B148: TH | C148: 12.744444
